<mujoco model="CyberMice">
    <compiler meshdir="Geometry" balanceinertia="true" angle="radian" eulerseq="xyz" />

    <option timestep="0.002" />
    <size njmax="1000" nconmax="400" nkey="1" nuser_jnt="1" />
    <statistic extent="1" />

    <visual>
        <scale forcewidth="0.01" contactwidth="0.03" contactheight="0.1" connect="0.002" framelength="5" com="0.1" selectpoint="0.05" framewidth="0.01" light="0.03" jointlength="1" jointwidth="0.02" constraint="0.05"/>
        <map stiffness="100" stiffnessrot="500" force="0.005" zfar="30" znear="1e-5"/>
        <rgba haze="0.15 0.25 0.35 0.5"/>
        <global offwidth="2560" offheight="1440" elevation="-20" azimuth="120"/>
        <headlight ambient="0.1 0.1 0.1" diffuse="0.8 0.8 0.8" specular="0.1 0.1 0.1"/>
    </visual>

    <default class="main">
        <joint limited="true" stiffness=".0" armature="1e-05" damping="1e-05" />
        <site rgba="0 0 0.8 1" size="0.0001 0.0001 0.0001" />
        <tendon limited="false" width="0.0001" rgba="0.95 0.3 0.3 1" />
        <default class="forelimbs">
            <geom type="mesh" contype="3" conaffinity="2" friction="0.7" solref="0.015 1" solimp="0.95 0.99 0.003" material="bone" />
        </default>
        <default class="muscle">
            <general ctrllimited="true" ctrlrange="0 1" dyntype="muscle" gaintype="muscle" biastype="muscle" dynprm="0.01 0.04 0 0 0 0 0 0 0 0" gainprm="0.75 1.05 -1 200 0.5 1.6 1.5 1.3 1.2 0" biasprm="0.75 1.05 -1 200 0.5 1.6 1.5 1.3 1.2 0" />
        </default>
        <default class="motor">
            <general gainprm="5 0 0 0 0 0 0 0 0 0" />
        </default>
        <default class="sensor">
            <site group="4" />
        </default>

        <default class="Thoracic">
            <joint group="3" pos="0.003 0 -0.003" armature="1e-05" damping="0.03"/>
            <general gainprm="0.15"/>
            <default class="Thoracic_x">
                <joint stiffness="0.03" range="-0.01 0.01"/>
                <tendon range="-1 1"/>
            </default>
            <default class="Thoracic_y">
                <joint stiffness="0.03" range="-0.01 0.01"/>
                <tendon range="-1 1"/>
            </default>
            <default class="Thoracic_z">
                <joint stiffness="0.02" range="-0.01 0.01"/>
                <tendon range="-1 1"/>
                <general gainprm="0.4"/>
            </default>
        </default>

        <default class="Lumbar">
            <joint group="3" pos="0.003 0 -0.003" armature="1e-05" damping="0.03"/>
            <general gainprm="0.15"/>
            <default class="Lumbar_x">
                <joint stiffness="0.03" range="-0.25 0.25"/>
                <tendon range="-1 1"/>
            </default>
            <default class="Lumbar_y">
                <joint stiffness="0.03" range="-0.25 0.25"/>
                <tendon range="-1 1"/>
            </default>
            <default class="Lumbar_z">
                <joint stiffness="0.02" range="-0.25 0.25"/>
                <tendon range="-1 1"/>
                <general gainprm="0.4"/>
            </default>
        </default>

        <default class="Cervical">
            <joint group="3" pos="-0.02 0 -0.05" stiffness="2.0" armature="0.001" damping="1.0"/>
            <default class="Cervical_x">
                <joint range="-0.18 0.18"/>
                <tendon range="-1 1"/>
                <general gainprm="2.5"/>
            </default>
            <default class="Cervical_y">
                <joint range="-0.18 0.18"/>
                <tendon range="-1 1"/>
                <general gainprm="2.5"/>
            </default>
            <default class="Cervical_z">
                <joint range="-0.18 0.18"/>
                <tendon range="-1 1"/>
                <general gainprm="2.5"/>
            </default>
        </default>

        <default class="Caudal">
            <joint group="3" stiffness="1e-05" damping="0.002"/>
            <general gainprm="0.005"/>
            <default class="Caudal_z">
                <joint range="-0.08726646259971647 0.08726646259971647"/>
                <tendon range="-0.05 0.05"/>
            </default>
            <default class="Caudal_y">
                <joint range="-0.08726646259971647 0.08726646259971647"/>
                <tendon range="-0.2 0.2"/>
            </default>
            <default class="Caudal_x">
                <joint range="-0.08726646259971647 0.08726646259971647"/>
                <tendon range="-0.2 0.2"/>
            </default>
        </default>

        <default class="collision">
            <geom contype="1" conaffinity="1" condim="1" group="1"/>
            <default class="collision_primitive">
                <geom type="capsule" group="1" rgba="0 0.5 0.5 0.5" density="500.0"/>
                <default class="collision_primitive_paw">
                    <geom condim="3" priority="1" rgba="0 0.6 0.7 0.5" friction="1.5 0.005 0.0001"/>
                </default>
                <default class="nonself_collision_primitive">
                    <geom conaffinity="0" rgba="0 0.5 0.5 0.5"/>
                </default>
            </default>
        </default>

    </default>


    <worldbody>
        <!-- <geom name="floor" type="plane" conaffinity="1" size="50 50 0.2" material="grid" pos="0 0 0" zaxis="0 0 1"/> -->
        <body name="T13" pos="0 0 0.05">
            <camera name="side" mode="trackcom" pos="0 -3.5 1" euler="-5 0 0" />
            <camera name="back" mode="trackcom" pos="-3.5 0 1.3" xyaxes="0 -1 0 1 0 3" />
            <light name="top" mode="trackcom" exponent="10" cutoff="45" ambient="0 0 0" pos="0 0 5" directional="false" />

            <!-- <joint name="root_x" type="slide" pos="0 0 0" axis="1 0 0" limited="false" stiffness="0" group="0" />
            <joint name="root_y" type="slide" pos="0 0 0" axis="0 1 0" limited="false" stiffness="0" group="0" />
            <joint name="root_z" type="slide" pos="0 0 0" axis="0 0 1" limited="false" stiffness="0" group="0" />
            <joint name="root_rot_x" pos="0 0 0" axis="1 0 0" limited="false" stiffness="0" group="0" />
            <joint name="root_rot_y" pos="0 0 0" axis="0 1 0" limited="false" stiffness="0" group="0" />
            <joint name="root_rot_z" pos="0 0 0" axis="0 0 1" limited="false" stiffness="0" group="0" /> -->

            <geom name="T13" pos="-0.0005 0 0.0002" euler="0 0 0.1" type="mesh" rgba="1 1 1 1" mesh="T13" density="1908"/>

            <site name="T13_SpinousProcess" pos="0.0005 0 0.0025" size="0.0005" rgba="1 1 0 1" group="4"/>
            <site name="T13_RTransverseProcess" pos="0.0005 -0.00175 0.001" size="0.0005" rgba="1 1 0 1" group="4"/>
            <site name="T13_LTransverseProcess" pos="0.0005 0.00175 0.001" size="0.0005" rgba="1 1 0 1" group="4"/>

            <site name="RLatissimusDorsi_4_3" pos="0.003 -0.005 0.001" size="0.0005" group="5" rgba="1 0 0 1"/>
            <site name="LLatissimusDorsi_4_3" pos="0.003 0.005 0.001" size="0.0005" group="5" rgba="1 0 0 1"/>

            <body name="Rib_13R" pos="0.002 -0.0015 0" gravcomp="0">
                <geom name="Rib_13R" pos="0 0 0" euler="0 -0.175 0.075" type="mesh" rgba="1 1 1 1" mesh="Rib_13R" density="1908"/>
                <joint name="Rib_13R_bucket" pos="0 0 0" axis="0.7 0 0.7" range="-0.1 0.1" group="5" />
                <joint name="Rib_13R_pump" pos="0 0 0" axis="-0.7 0 0.7" range="-0.1 0.1" group="5" />

                <site name="T13_RRibAngle" pos="-0.00075 -0.002 0.0008" size="0.0005" group="4" rgba="1 1 0 1"/>
                <site name="Rib13Rinter" pos="-0.000507 -0.002149 0.000711" size="0.0005" group="5" rgba="1 0 0 1" />
            </body>

            <body name="Rib_13L" pos="0.002 0.0015 0" gravcomp="0">
                <geom name="Rib_13L" pos="0 0 0" euler="0 -0.175 0.075" type="mesh" rgba="1 1 1 1" mesh="Rib_13L" density="1908"/>
                <joint name="Rib_13L_bucket" pos="0 0 0" axis="-0.7 0 -0.7" range="-0.1 0.1" group="5" />
                <joint name="Rib_13L_pump" pos="0 0 0" axis="0.7 0 -0.7" range="-0.1 0.1" group="5" />

                <site name="T13_LRibAngle" pos="-0.00075 0.002 0.0008" size="0.0005" group="4" rgba="1 1 0 1"/>
                <site name="Rib13Linter" pos="-0.000507 0.002149 0.000711" size="0.0005" group="5" rgba="1 0 0 1" />
            </body>
            <include file="Body/Body_Torso.xml"/>
            <include file="Body/Body_L1_Pelvis.xml"/>
        </body>
    </worldbody>

    <asset>
        <texture name="skybox" type="skybox" builtin="gradient" rgb1="0.4 0.6 0.8" rgb2="0 0 0" mark="random" markrgb="1 1 1" width="800" height="800" />
        <texture name="plane" type="2d" builtin="checker" rgb1="0.2 0.3 0.4" rgb2="0.3 0.4 0.5" width="10" height="10" />
        <material name="plane" texture="plane" texrepeat="5 5" reflectance="0.2" />
        <texture name="grid" type="2d" builtin="checker" rgb1="0.1 0.2 0.3" rgb2="0.2 0.3 0.4" mark="edge" markrgb="0.2 0.3 0.4" width="300" height="300" />
        <material name="grid" texture="grid" texrepeat="1 1" texuniform="true" reflectance="0.2" />
    </asset>

    <include file="Asset/Asset_Arms.xml"/>
    <include file="Asset/Asset_Legs.xml"/>
    <include file="Asset/Asset_Torso.xml"/>


    <include file="Tendon/Tendon_Arm_r.xml"/>
    <include file="Tendon/Tendon_Arm_l.xml"/>
    <include file="Tendon/Tendon_Leg_r.xml"/>
    <include file="Tendon/Tendon_Leg_l.xml"/>
    <include file="Tendon/Tendon_Torso_r.xml"/>
    <include file="Tendon/Tendon_Torso_l.xml"/>

    <include file="Muscle/Muscle_Arm_r.xml"/>
    <include file="Muscle/Muscle_Arm_l.xml"/>
    <include file="Muscle/Muscle_Leg_r.xml"/>
    <include file="Muscle/Muscle_Leg_l.xml"/>
    <include file="Muscle/Muscle_Torso_r.xml"/>
    <include file="Muscle/Muscle_Torso_l.xml"/>

    <include file="Equality/Equality.xml"/>

    <sensor>
        <subtreelinvel name="torso_subtreelinvel" body="T13" />
        <subtreecom name="body_com" body="T13" />
    </sensor>

</mujoco>
